Workbook

Sheet Base Insumos
A1: Código | B1: Descrição | C1: Custo Unit. (R$) | D1: Unidade | E1: Observação | F1: Últ. Atualização
A2: 000372 | B2: =IFERROR(VLOOKUP(A2,_Protheus_Cadastro!$A:$B,2,FALSE),"PENDENTE") | C2: =IFERROR(VLOOKUP(A2,_Protheus_Cadastro!$A:$G,7,FALSE),0) | D2: =IFERROR(VLOOKUP(A2,_Protheus_Cadastro!$A:$D,4,FALSE),"") | F2: 13/05/2026
A3: 000404 | B3: =IFERROR(VLOOKUP(A3,_Protheus_Cadastro!$A:$B,2,FALSE),"PENDENTE") | C3: =IFERROR(VLOOKUP(A3,_Protheus_Cadastro!$A:$G,7,FALSE),0) | D3: =IFERROR(VLOOKUP(A3,_Protheus_Cadastro!$A:$D,4,FALSE),"") | F3: 13/05/2026
A4: 000487 | B4: =IFERROR(VLOOKUP(A4,_Protheus_Cadastro!$A:$B,2,FALSE),"PENDENTE") | C4: =IFERROR(VLOOKUP(A4,_Protheus_Cadastro!$A:$G,7,FALSE),0) | D4: =IFERROR(VLOOKUP(A4,_Protheus_Cadastro!$A:$D,4,FALSE),"") | F4: 13/05/2026
A5: 000624 | B5: =IFERROR(VLOOKUP(A5,_Protheus_Cadastro!$A:$B,2,FALSE),"PENDENTE") | C5: =IFERROR(VLOOKUP(A5,_Protheus_Cadastro!$A:$G,7,FALSE),0) | D5: =IFERROR(VLOOKUP(A5,_Protheus_Cadastro!$A:$D,4,FALSE),"") | F5: 13/05/2026
A6: 001972 | B6: =IFERROR(VLOOKUP(A6,_Protheus_Cadastro!$A:$B,2,FALSE),"PENDENTE") | C6: =IFERROR(VLOOKUP(A6,_Protheus_Cadastro!$A:$G,7,FALSE),0) | D6: =IFERROR(VLOOKUP(A6,_Protheus_Cadastro!$A:$D,4,FALSE),"") | F6: 13/05/2026
A7: 000459 | B7: =IFERROR(VLOOKUP(A7,_Protheus_Cadastro!$A:$B,2,FALSE),"PENDENTE") | C7: =IFERROR(VLOOKUP(A7,_Protheus_Cadastro!$A:$G,7,FALSE),0) | D7: =IFERROR(VLOOKUP(A7,_Protheus_Cadastro!$A:$D,4,FALSE),"") | F7: 13/05/2026
A8: 000700 | B8: =IFERROR(VLOOKUP(A8,_Protheus_Cadastro!$A:$B,2,FALSE),"PENDENTE") | C8: =IFERROR(VLOOKUP(A8,_Protheus_Cadastro!$A:$G,7,FALSE),0) | D8: =IFERROR(VLOOKUP(A8,_Protheus_Cadastro!$A:$D,4,FALSE),"") | F8: 13/05/2026
A9: 000374 | B9: =IFERROR(VLOOKUP(A9,_Protheus_Cadastro!$A:$B,2,FALSE),"PENDENTE") | C9: =IFERROR(VLOOKUP(A9,_Protheus_Cadastro!$A:$G,7,FALSE),0) | D9: =IFERROR(VLOOKUP(A9,_Protheus_Cadastro!$A:$D,4,FALSE),"") | F9: 13/05/2026
A10: 000460 | B10: =IFERROR(VLOOKUP(A10,_Protheus_Cadastro!$A:$B,2,FALSE),"PENDENTE") | C10: =IFERROR(VLOOKUP(A10,_Protheus_Cadastro!$A:$G,7,FALSE),0) | D10: =IFERROR(VLOOKUP(A10,_Protheus_Cadastro!$A:$D,4,FALSE),"") | F10: 13/05/2026
A11: 000334 | B11: =IFERROR(VLOOKUP(A11,_Protheus_Cadastro!$A:$B,2,FALSE),"PENDENTE") | C11: =IFERROR(VLOOKUP(A11,_Protheus_Cadastro!$A:$G,7,FALSE),0) | D11: =IFERROR(VLOOKUP(A11,_Protheus_Cadastro!$A:$D,4,FALSE),"") | F11: 13/05/2026
A12: 000380 | B12: =IFERROR(VLOOKUP(A12,_Protheus_Cadastro!$A:$B,2,FALSE),"PENDENTE") | C12: =IFERROR(VLOOKUP(A12,_Protheus_Cadastro!$A:$G,7,FALSE),0) | D12: =IFERROR(VLOOKUP(A12,_Protheus_Cadastro!$A:$D,4,FALSE),"") | F12: 13/05/2026
A13: 000333 | B13: =IFERROR(VLOOKUP(A13,_Protheus_Cadastro!$A:$B,2,FALSE),"PENDENTE") | C13: =IFERROR(VLOOKUP(A13,_Protheus_Cadastro!$A:$G,7,FALSE),0) | D13: =IFERROR(VLOOKUP(A13,_Protheus_Cadastro!$A:$D,4,FALSE),"") | F13: 13/05/2026
... A21: 001975 | B21: =IFERROR(VLOOKUP(A21,_Protheus_Cadastro!$A:$B,2,FALSE),"PENDENTE") | C21: =IFERROR(VLOOKUP(A21,_Protheus_Cadastro!$A:$G,7,FALSE),0) | D21: =IFERROR(VLOOKUP(A21,_Protheus_Cadastro!$A:$D,4,FALSE),"") | F21: 13/05/2026
A22: 009947 | B22: =IFERROR(VLOOKUP(A22,_Protheus_Cadastro!$A:$B,2,FALSE),"PENDENTE") | C22: =IFERROR(VLOOKUP(A22,_Protheus_Cadastro!$A:$G,7,FALSE),0) | D22: =IFERROR(VLOOKUP(A22,_Protheus_Cadastro!$A:$D,4,FALSE),"") | E22: Muita diferença de valor para o de 100ml | F22: 13/05/2026
A23: 001176 | B23: =IFERROR(VLOOKUP(A23,_Protheus_Cadastro!$A:$B,2,FALSE),"PENDENTE") | C23: =IFERROR(VLOOKUP(A23,_Protheus_Cadastro!$A:$G,7,FALSE),0) | D23: =IFERROR(VLOOKUP(A23,_Protheus_Cadastro!$A:$D,4,FALSE),"") | F23: 13/05/2026
A24: 000337 | B24: =IFERROR(VLOOKUP(A24,_Protheus_Cadastro!$A:$B,2,FALSE),"PENDENTE") | C24: =IFERROR(VLOOKUP(A24,_Protheus_Cadastro!$A:$G,7,FALSE),0) | D24: =IFERROR(VLOOKUP(A24,_Protheus_Cadastro!$A:$D,4,FALSE),"") | F24: 13/05/2026
A25: 000345 | B25: =IFERROR(VLOOKUP(A25,_Protheus_Cadastro!$A:$B,2,FALSE),"PENDENTE") | C25: =IFERROR(VLOOKUP(A25,_Protheus_Cadastro!$A:$G,7,FALSE),0) | D25: =IFERROR(VLOOKUP(A25,_Protheus_Cadastro!$A:$D,4,FALSE),"") | F25: 13/05/2026
A26: 000377 | B26: =IFERROR(VLOOKUP(A26,_Protheus_Cadastro!$A:$B,2,FALSE),"PENDENTE") | C26: =IFERROR(VLOOKUP(A26,_Protheus_Cadastro!$A:$G,7,FALSE),0) | D26: =IFERROR(VLOOKUP(A26,_Protheus_Cadastro!$A:$D,4,FALSE),"") | F26: 13/05/2026
A27: 001043 | B27: =IFERROR(VLOOKUP(A27,_Protheus_Cadastro!$A:$B,2,FALSE),"PENDENTE") | C27: =IFERROR(VLOOKUP(A27,_Protheus_Cadastro!$A:$G,7,FALSE),0) | D27: =IFERROR(VLOOKUP(A27,_Protheus_Cadastro!$A:$D,4,FALSE),"") | F27: 13/05/2026
A28: 010225 | B28: =IFERROR(VLOOKUP(A28,_Protheus_Cadastro!$A:$B,2,FALSE),"PENDENTE") | C28: =IFERROR(VLOOKUP(A28,_Protheus_Cadastro!$A:$G,7,FALSE),0) | D28: =IFERROR(VLOOKUP(A28,_Protheus_Cadastro!$A:$D,4,FALSE),"") | F28: 13/05/2026
A29: 000747 | B29: =IFERROR(VLOOKUP(A29,_Protheus_Cadastro!$A:$B,2,FALSE),"PENDENTE") | C29: =IFERROR(VLOOKUP(A29,_Protheus_Cadastro!$A:$G,7,FALSE),0) | D29: =IFERROR(VLOOKUP(A29,_Protheus_Cadastro!$A:$D,4,FALSE),"") | F29: 13/05/2026
A30: 001995 | B30: =IFERROR(VLOOKUP(A30,_Protheus_Cadastro!$A:$B,2,FALSE),"PENDENTE") | C30: =IFERROR(VLOOKUP(A30,_Protheus_Cadastro!$A:$G,7,FALSE),0) | D30: =IFERROR(VLOOKUP(A30,_Protheus_Cadastro!$A:$D,4,FALSE),"") | F30: 13/05/2026
A31: 000426 | B31: =IFERROR(VLOOKUP(A31,_Protheus_Cadastro!$A:$B,2,FALSE),"PENDENTE") | C31: =IFERROR(VLOOKUP(A31,_Protheus_Cadastro!$A:$G,7,FALSE),0) | D31: =IFERROR(VLOOKUP(A31,_Protheus_Cadastro!$A:$D,4,FALSE),"") | F31: 13/05/2026
A32: 009487 | B32: =IFERROR(VLOOKUP(A32,_Protheus_Cadastro!$A:$B,2,FALSE),"PENDENTE") | C32: =IFERROR(VLOOKUP(A32,_Protheus_Cadastro!$A:$G,7,FALSE),0) | D32: =IFERROR(VLOOKUP(A32,_Protheus_Cadastro!$A:$D,4,FALSE),"") | F32: 13/05/2026
A33: 009486 | B33: =IFERROR(VLOOKUP(A33,_Protheus_Cadastro!$A:$B,2,FALSE),"PENDENTE") | C33: =IFERROR(VLOOKUP(A33,_Protheus_Cadastro!$A:$G,7,FALSE),0) | D33: =IFERROR(VLOOKUP(A33,_Protheus_Cadastro!$A:$D,4,FALSE),"") | F33: 13/05/2026
A34: 000488 | B34: =IFERROR(VLOOKUP(A34,_Protheus_Cadastro!$A:$B,2,FALSE),"PENDENTE") | C34: =IFERROR(VLOOKUP(A34,_Protheus_Cadastro!$A:$G,7,FALSE),0) | D34: =IFERROR(VLOOKUP(A34,_Protheus_Cadastro!$A:$D,4,FALSE),"") | F34: 13/05/2026
... A51: 000304 | B51: =IFERROR(VLOOKUP(A51,_Protheus_Cadastro!$A:$B,2,FALSE),"PENDENTE") | C51: =IFERROR(VLOOKUP(A51,_Protheus_Cadastro!$A:$G,7,FALSE),0) | D51: =IFERROR(VLOOKUP(A51,_Protheus_Cadastro!$A:$D,4,FALSE),"") | F51: 13/05/2026
A52: 000306 | B52: =IFERROR(VLOOKUP(A52,_Protheus_Cadastro!$A:$B,2,FALSE),"PENDENTE") | C52: =IFERROR(VLOOKUP(A52,_Protheus_Cadastro!$A:$G,7,FALSE),0) | D52: =IFERROR(VLOOKUP(A52,_Protheus_Cadastro!$A:$D,4,FALSE),"") | E52: Confirmar em qual PA usamos esse componente (prato novo?) | F52: 13/05/2026
A53: 009090 | B53: =IFERROR(VLOOKUP(A53,_Protheus_Cadastro!$A:$B,2,FALSE),"PENDENTE") | C53: =IFERROR(VLOOKUP(A53,_Protheus_Cadastro!$A:$G,7,FALSE),0) | D53: =IFERROR(VLOOKUP(A53,_Protheus_Cadastro!$A:$D,4,FALSE),"") | F53: 13/05/2026
A54: 001133 | B54: =IFERROR(VLOOKUP(A54,_Protheus_Cadastro!$A:$B,2,FALSE),"PENDENTE") | C54: =IFERROR(VLOOKUP(A54,_Protheus_Cadastro!$A:$G,7,FALSE),0) | D54: =IFERROR(VLOOKUP(A54,_Protheus_Cadastro!$A:$D,4,FALSE),"") | F54: 13/05/2026
A55: 000327 | B55: =IFERROR(VLOOKUP(A55,_Protheus_Cadastro!$A:$B,2,FALSE),"PENDENTE") | C55: =IFERROR(VLOOKUP(A55,_Protheus_Cadastro!$A:$G,7,FALSE),0) | D55: =IFERROR(VLOOKUP(A55,_Protheus_Cadastro!$A:$D,4,FALSE),"") | F55: 13/05/2026
A56: 000467 | B56: =IFERROR(VLOOKUP(A56,_Protheus_Cadastro!$A:$B,2,FALSE),"PENDENTE") | C56: =IFERROR(VLOOKUP(A56,_Protheus_Cadastro!$A:$G,7,FALSE),0) | D56: =IFERROR(VLOOKUP(A56,_Protheus_Cadastro!$A:$D,4,FALSE),"") | F56: 13/05/2026
A57: 000326 | B57: =IFERROR(VLOOKUP(A57,_Protheus_Cadastro!$A:$B,2,FALSE),"PENDENTE") | C57: =IFERROR(VLOOKUP(A57,_Protheus_Cadastro!$A:$G,7,FALSE),0) | D57: =IFERROR(VLOOKUP(A57,_Protheus_Cadastro!$A:$D,4,FALSE),"") | F57: 13/05/2026
A58: 001346 | B58: =IFERROR(VLOOKUP(A58,_Protheus_Cadastro!$A:$B,2,FALSE),"PENDENTE") | C58: =IFERROR(VLOOKUP(A58,_Protheus_Cadastro!$A:$G,7,FALSE),0) | D58: =IFERROR(VLOOKUP(A58,_Protheus_Cadastro!$A:$D,4,FALSE),"") | F58: 13/05/2026
A59: 001988 | B59: =IFERROR(VLOOKUP(A59,_Protheus_Cadastro!$A:$B,2,FALSE),"PENDENTE") | C59: =IFERROR(VLOOKUP(A59,_Protheus_Cadastro!$A:$G,7,FALSE),0) | D59: =IFERROR(VLOOKUP(A59,_Protheus_Cadastro!$A:$D,4,FALSE),"") | F59: 13/05/2026
A60: 000760 | B60: =IFERROR(VLOOKUP(A60,_Protheus_Cadastro!$A:$B,2,FALSE),"PENDENTE") | C60: =IFERROR(VLOOKUP(A60,_Protheus_Cadastro!$A:$G,7,FALSE),0) | D60: =IFERROR(VLOOKUP(A60,_Protheus_Cadastro!$A:$D,4,FALSE),"") | F60: 13/05/2026
A61: 000759 | B61: =IFERROR(VLOOKUP(A61,_Protheus_Cadastro!$A:$B,2,FALSE),"PENDENTE") | C61: =IFERROR(VLOOKUP(A61,_Protheus_Cadastro!$A:$G,7,FALSE),0) | D61: =IFERROR(VLOOKUP(A61,_Protheus_Cadastro!$A:$D,4,FALSE),"") | F61: 13/05/2026
A62: 000758 | B62: =IFERROR(VLOOKUP(A62,_Protheus_Cadastro!$A:$B,2,FALSE),"PENDENTE") | C62: =IFERROR(VLOOKUP(A62,_Protheus_Cadastro!$A:$G,7,FALSE),0) | D62: =IFERROR(VLOOKUP(A62,_Protheus_Cadastro!$A:$D,4,FALSE),"") | F62: 13/05/2026
A63: 000756 | B63: =IFERROR(VLOOKUP(A63,_Protheus_Cadastro!$A:$B,2,FALSE),"PENDENTE") | C63: =IFERROR(VLOOKUP(A63,_Protheus_Cadastro!$A:$G,7,FALSE),0) | D63: =IFERROR(VLOOKUP(A63,_Protheus_Cadastro!$A:$D,4,FALSE),"") | E63: Preciso do valor da garrafa | F63: 13/05/2026
...

Sheet Estrutura Protheus
A1: Codigo | B1: Componente | C1: Descricao | D1: Sequencia | E1: Quantidade | F1: Cust Med Ini | G1: Cust Med Atu | H1: Indice Perda | I1: Potencia | J1: Armazem | K1: Fantasma? | L1: Lista | M1: Custo Medio
A2: 002238 | B2: 000454 | C2: BATATA MCAIM 9 MM 2,5KG | E2: 0.15 | F2: 0 | G2: 0 | H2: 0 | I2: 0 | M2: 0
A3: 000001 | B3: 000286 | C3: ESPETO BOVINO | E3: 7 | F3: 0 | G3: 0 | H3: 0 | I3: 0 | M3: 0
A4: 000002 | B4: 000287 | C4: ESPETO CALABRESA C/ PIMENTA | E4: 6 | F4: 0 | G4: 0 | H4: 0 | I4: 0 | M4: 0
A5: 000003 | B5: 000288 | C5: ESPETO CALABRESA S/ PIMENTA | E5: 6 | F5: 0 | G5: 0 | H5: 0 | I5: 0 | M5: 0
A6: 000004 | B6: 000289 | C6: ESPETO CORACAO | E6: 7 | F6: 3161.03 | G6: 0 | H6: 0 | I6: 0 | M6: 0
A7: 000005 | B7: 000290 | C7: ESPETO COSTELINHA BOVINA | E7: 7 | F7: 24252.4 | G7: 0 | H7: 0 | I7: 0 | M7: 0
A8: 000006 | B8: 000291 | C8: ESPETO FRANGO | E8: 7 | F8: 1983.5 | G8: 0 | H8: 0 | I8: 0 | M8: 0
A9: 000007 | B9: 000293 | C9: ESPETO KAFTA | E9: 7 | F9: 10882.88 | G9: 0 | H9: 0 | I9: 0 | M9: 0
A10: 000008 | B10: 000439 | C10: ESPETO QUEIJO COALHO | E10: 0.42 | F10: 0 | G10: 0 | H10: 0 | I10: 0 | M10: 0
A11: 000009 | B11: 000027 | C11: SALSICHAO | E11: 10 | F11: 0 | G11: 0 | H11: 0 | I11: 0 | M11: 0
A12: 000010 | B12: 000292 | C12: ESPETO TULIPA | E12: 5 | F12: 48.42 | G12: 0 | H12: 0 | I12: 0 | M12: 0
A13: 000011 | B13: 000297 | C13: ESPETO PICANHA C/ GORDURA | E13: 7 | F13: 11824.87 | G13: 0 | H13: 0 | I13: 0 | M13: 0
... A257: 001056 | B257: 001044 | C257: MINI CHURROS | E257: 4 | F257: 532.02 | G257: 0 | H257: 0 | I257: 0 | M257: 0
A258: 001069 | B258: 001050 | C258: MINI PASTEL DE CARNE | D258: 001 | E258: 3 | F258: 171.34 | G258: 0 | H258: 0 | I258: 0 | M258: 0
A259: 001069 | B259: 001051 | C259: MINI PASTEL DE QUEIJO | D259: 002 | E259: 2 | F259: 86.72 | G259: 0 | H259: 0 | I259: 0 | M259: 0
A260: 001070 | B260: 000445 | C260: TOLETE DE PUPUNHA 1,8KG | E260: 0.11 | F260: 0 | G260: 0 | H260: 0 | I260: 0 | M260: 0
A261: 001070 | B261: 000614 | C261: SAL REFINADO | E261: 0.001 | F261: 0 | G261: 0 | H261: 0 | I261: 0 | M261: 0
A262: 001070 | B262: 000667 | C262: TOMILHO | E262: 0.005 | F262: 0 | G262: 0 | H262: 0 | I262: 0 | M262: 0
A263: 001072 | B263: 000290 | C263: ESPETO COSTELINHA BOVINA | E263: 1 | F263: 0 | G263: 0 | H263: 0 | I263: 0 | M263: 0
A264: 001078 | B264: 000318 | C264: TONICA COMUM LATA | E264: 0.5 | F264: 0 | G264: 0 | H264: 0 | I264: 0 | M264: 0
A265: 001078 | B265: 000492 | C265: LIMAO TAITI FRUTA | E265: 0.05 | F265: 0 | G265: 0 | H265: 0 | I265: 0 | M265: 0
A266: 001078 | B266: 000668 | C266: ALECRIM | E266: 0.015 | F266: 0 | G266: 0 | H266: 0 | I266: 0 | M266: 0
A267: 001078 | B267: 001173 | C267: ZIMBRO | E267: 0.003 | F267: 0 | G267: 0 | H267: 0 | I267: 0 | M267: 0
A268: 001081 | B268: 000453 | C268: CANELA EM PAU (4CM) | E268: 0.01 | F268: 0 | G268: 0 | H268: 0 | I268: 0 | M268: 0
A269: 001081 | B269: 000490 | C269: LARANJA PERA FRUTA | E269: 0.12 | F269: 0 | G269: 0 | H269: 0 | I269: 0 | M269: 0
A270: 001081 | B270: 000749 | C270: RED BULL TROPICAL | E270: 1 | F270: 0 | G270: 0 | H270: 0 | I270: 0 | M270: 0
A271: 001082 | B271: 000292 | C271: ESPETO TULIPA | E271: 1 | F271: 0 | G271: 0 | H271: 0 | I271: 0 | M271: 0
... A617: 002023 | B617: 002068 | C617: MANTEIGA S/SAL 5KG | E617: 0.005 | F617: 0 | G617: 0 | H617: 0 | I617: 0 | M617: 0
A618: 002023 | B618: 002068 | C618: MANTEIGA S/SAL 5KG | D618: 001 | E618: 0.004 | F618: 0 | G618: 0 | H618: 0 | I618: 0 | M618: 0
A619: 002023 | B619: 002070 | C619: ALHO PORO | E619: 0.004 | F619: 0 | G619: 0 | H619: 0 | I619: 0 | M619: 0
A620: 002024 | B620: 000286 | C620: ESPETO BOVINO | E620: 4 | F620: 16513.59 | G620: 0 | H620: 0 | I620: 0 | M620: 0
A621: 002024 | B621: 000288 | C621: ESPETO CALABRESA S/ PIMENTA | E621: 3 | F621: 3320.34 | G621: 0 | H621: 0 | I621: 0 | M621: 0
A622: 002024 | B622: 000289 | C622: ESPETO CORACAO | E622: 3 | F622: 22784.8 | G622: 0 | H622: 0 | I622: 0 | M622: 0
A623: 002024 | B623: 000291 | C623: ESPETO FRANGO | E623: 4 | F623: 991.75 | G623: 0 | H623: 0 | I623: 0 | M623: 0
A624: 002024 | B624: 000296 | C624: ESPETO FILE MIGNON | E624: 4 | F624: 5713.51 | G624: 0 | H624: 0 | I624: 0 | M624: 0
A625: 002024 | B625: 000331 | C625: BARRIL CHOPP BRAHMA CLARO 50LT | E625: 0.003 | F625: 0 | G625: 0 | H625: 0 | I625: 0 | M625: 0
A626: 002024 | B626: 000377 | C626: ARROZ TIPO 1 | E626: 0.06 | F626: 0 | G626: 0 | H626: 0 | I626: 0 | M626: 0
A627: 002024 | B627: 000390 | C627: FARINHA DE TRIGO SOL | E627: 0.002 | F627: 0 | G627: 0 | H627: 0 | I627: 0 | M627: 0
A628: 002024 | B628: 000412 | C628: OLEO DE SOJA LIZA 900ML | E628: 0.059 | F628: 0 | G628: 0 | H628: 0 | I628: 0 | M628: 0
...

Sheet Fichas Flat
A1: Categoria | B1: Subcategoria | C1: Nome do PA | D1: Estrutura criada | E1: Código PA | F1: Cód. Componente | G1: Descrição Componente | H1: Qtd | I1: Und. | J1: Custo Unit. (R$) | K1: Custo Ingr. (R$) | L1: Preço Venda (R$) | M1: CMV (%) | N1: Observação
A2: Espetos | B2: Veggie | C2: Abóbora Assada | D2: =IF(ISERROR(VLOOKUP(E2,'Estrutura Protheus'!A:A,1,FALSE)),"Não","Sim") | E2: 002124 | F2: 000624 | G2: Abobora Japonesa | H2: 0.12 | I2: KG | J2: =IFERROR(VLOOKUP(F2,'Base Insumos'!$A:$C,3,FALSE()),"PENDENTE") | K2: =IFERROR(IF(J2="PENDENTE",0,J2*H2),0) | L2: 10.99 | M2: =IFERROR(K2/L2,0)
A3: Espetos | B3: Veggie | C3: Abobrinha Grelhada | D3: =IF(ISERROR(VLOOKUP(E3,'Estrutura Protheus'!A:A,1,FALSE)),"Não","Sim") | E3: 001508 | F3: 000459 | G3: Abobrinha Italiana | H3: 0.1 | I3: KG | J3: =IFERROR(VLOOKUP(F3,'Base Insumos'!$A:$C,3,FALSE()),"PENDENTE") | K3: =IFERROR(IF(J3="PENDENTE",0,J3*H3),0) | L3: 10.99 | M3: =IFERROR(K3/L3,0)
A4: Espetos | B4: Veggie | C4: Batata Bolinha | D4: =IF(ISERROR(VLOOKUP(E4,'Estrutura Protheus'!A:A,1,FALSE)),"Não","Sim") | E4: 001507 | F4: 000464 | G4: Batata Bolinha | H4: 0.1 | I4: KG | J4: =IFERROR(VLOOKUP(F4,'Base Insumos'!$A:$C,3,FALSE()),"PENDENTE") | K4: =IFERROR(IF(J4="PENDENTE",0,J4*H4),0) | L4: 10.99 | M4: =IFERROR(K4/L4,0)
A5: Espetos | B5: Veggie | C5: Berinjela Grelhada | D5: =IF(ISERROR(VLOOKUP(E5,'Estrutura Protheus'!A:A,1,FALSE)),"Não","Sim") | E5: 001505 | F5: 000466 | G5: Berinjela | H5: 0.1 | I5: KG | J5: =IFERROR(VLOOKUP(F5,'Base Insumos'!$A:$C,3,FALSE()),"PENDENTE") | K5: =IFERROR(IF(J5="PENDENTE",0,J5*H5),0) | L5: 10.99 | M5: =IFERROR(K5/L5,0)
A6: Espetos | B6: Premium | C6: Bolinho de Bacalhau | D6: =IF(ISERROR(VLOOKUP(E6,'Estrutura Protheus'!A:A,1,FALSE)),"Não","Sim") | E6: 000766 | F6: 000305 | G6: Bolinho de Bacalhau | H6: 4 | I6: UN | J6: =IFERROR(VLOOKUP(F6,'Base Insumos'!$A:$C,3,FALSE()),"PENDENTE") | K6: =IFERROR(IF(J6="PENDENTE",0,J6*H6),0) | L6: 14.99 | M6: =IFERROR(K6/L6,0)
A7: Espetos | B7: Boteco no Espeto | C7: Bolinho de Queijo | D7: =IF(ISERROR(VLOOKUP(E7,'Estrutura Protheus'!A:A,1,FALSE)),"Não","Sim") | E7: 000769 | F7: 000304 | G7: Bolinho de Queijo | H7: 4 | I7: UN | J7: =IFERROR(VLOOKUP(F7,'Base Insumos'!$A:$C,3,FALSE()),"PENDENTE") | K7: =IFERROR(IF(J7="PENDENTE",0,J7*H7),0) | L7: 14.99 | M7: =IFERROR(K7/L7,0)
A8: Espetos | B8: In Natura | C8: Bovino | D8: =IF(ISERROR(VLOOKUP(E8,'Estrutura Protheus'!A:A,1,FALSE)),"Não","Sim") | E8: 000001 | F8: 000286 | G8: Espeto Bovino | H8: 7 | I8: UN | J8: =IFERROR(VLOOKUP(F8,'Base Insumos'!$A:$C,3,FALSE()),"PENDENTE") | K8: =IFERROR(IF(J8="PENDENTE",0,J8*H8),0) | L8: 29.9 | M8: =IFERROR(K8/L8,0)
A9: Espetos | B9: Tradicional | C9: Calabresa com Pimenta | D9: =IF(ISERROR(VLOOKUP(E9,'Estrutura Protheus'!A:A,1,FALSE)),"Não","Sim") | E9: 000021 | F9: 000287 | G9: Espeto Calabresa c/ Pimenta | H9: 1 | I9: UN | J9: =IFERROR(VLOOKUP(F9,'Base Insumos'!$A:$C,3,FALSE()),"PENDENTE") | K9: =IFERROR(IF(J9="PENDENTE",0,J9*H9),0) | L9: 13.99 | M9: =IFERROR(K9/L9,0)
A10: Espetos | B10: In Natura | C10: Calabresa com Pimenta | D10: =IF(ISERROR(VLOOKUP(E10,'Estrutura Protheus'!A:A,1,FALSE)),"Não","Sim") | E10: 000002 | F10: 000287 | G10: Espeto Calabresa c/ Pimenta | H10: 6 | I10: UN | J10: =IFERROR(VLOOKUP(F10,'Base Insumos'!$A:$C,3,FALSE()),"PENDENTE") | K10: =IFERROR(IF(J10="PENDENTE",0,J10*H10),0) | L10: 34.9 | M10: =IFERROR(K10/L10,0)
A11: Espetos | B11: Tradicional | C11: Calabresa sem Pimenta | D11: =IF(ISERROR(VLOOKUP(E11,'Estrutura Protheus'!A:A,1,FALSE)),"Não","Sim") | E11: 000022 | F11: 000288 | G11: Espeto Calabresa s/ Pimenta | H11: 1 | I11: UN | J11: =IFERROR(VLOOKUP(F11,'Base Insumos'!$A:$C,3,FALSE()),"PENDENTE") | K11: =IFERROR(IF(J11="PENDENTE",0,J11*H11),0) | L11: 13.99 | M11: =IFERROR(K11/L11,0)
A12: Espetos | B12: In Natura | C12: Calabresa sem Pimenta | D12: =IF(ISERROR(VLOOKUP(E12,'Estrutura Protheus'!A:A,1,FALSE)),"Não","Sim") | E12: 000003 | F12: 000288 | G12: Espeto Calabresa s/ Pimenta | H12: 6 | I12: UN | J12: =IFERROR(VLOOKUP(F12,'Base Insumos'!$A:$C,3,FALSE()),"PENDENTE") | K12: =IFERROR(IF(J12="PENDENTE",0,J12*H12),0) | L12: 34.9 | M12: =IFERROR(K12/L12,0)
A13: Espetos | B13: Premium | C13: Camarão | D13: =IF(ISERROR(VLOOKUP(E13,'Estrutura Protheus'!A:A,1,FALSE)),"Não","Sim") | E13: 000364 | F13: 000302 | G13: Espeto Camarao Comum | H13: 1 | I13: UN | J13: =IFERROR(VLOOKUP(F13,'Base Insumos'!$A:$C,3,FALSE()),"PENDENTE") | K13: =IFERROR(IF(J13="PENDENTE",0,J13*H13),0) | L13: 19.99 | M13: =IFERROR(K13/L13,0)
... A42: Espetos | B42: Direto da Fazenda | C42: Queijo Coalho | D42: =IF(ISERROR(VLOOKUP(E42,'Estrutura Protheus'!A:A,1,FALSE)),"Não","Sim") | E42: 000282 | F42: 000439 | G42: Espeto Queijo Coalho | H42: 0.06 | I42: KG | J42: =IFERROR(VLOOKUP(F42,'Base Insumos'!$A:$C,3,FALSE()),"PENDENTE") | K42: =IFERROR(IF(J42="PENDENTE",0,J42*H42),0) | L42: 13.99 | M42: =IFERROR(K42/L42,0)
A43: Espetos | B43: In Natura | C43: Queijo Coalho | D43: =IF(ISERROR(VLOOKUP(E43,'Estrutura Protheus'!A:A,1,FALSE)),"Não","Sim") | E43: 000008 | F43: 000439 | G43: Espeto Queijo Coalho | H43: =0.06*7 | I43: KG | J43: =IFERROR(VLOOKUP(F43,'Base Insumos'!$A:$C,3,FALSE()),"PENDENTE") | K43: =IFERROR(IF(J43="PENDENTE",0,J43*H43),0) | L43: 29.9 | M43: =IFERROR(K43/L43,0)
A44: Espetos | B44: Tradicional | C44: Salsichão | D44: =IF(ISERROR(VLOOKUP(E44,'Estrutura Protheus'!A:A,1,FALSE)),"Não","Sim") | E44: 000027 | F44: 000298 | G44: Espeto Salsichao | H44: 1 | I44: UN | J44: =IFERROR(VLOOKUP(F44,'Base Insumos'!$A:$C,3,FALSE()),"PENDENTE") | K44: =IFERROR(IF(J44="PENDENTE",0,J44*H44),0) | L44: 14.99 | M44: =IFERROR(K44/L44,0)
A45: Espetos | B45: Premium | C45: Salsichão c/ Provolone | D45: =IF(ISERROR(VLOOKUP(E45,'Estrutura Protheus'!A:A,1,FALSE)),"Não","Sim") | E45: 000765 | F45: 000301 | G45: Espeto Salsichao c/ Provolone | H45: 1 | I45: UN | J45: =IFERROR(VLOOKUP(F45,'Base Insumos'!$A:$C,3,FALSE()),"PENDENTE") | K45: =IFERROR(IF(J45="PENDENTE",0,J45*H45),0) | L45: 17.99 | M45: =IFERROR(K45/L45,0)
A46: Espetos | B46: Boteco no Espeto | C46: Sticks de Muçarela | D46: =IF(ISERROR(VLOOKUP(E46,'Estrutura Protheus'!A:A,1,FALSE)),"Não","Sim") | E46: 001472 | F46: 001580 | G46: Palito Mussarela 1kg | H46: 0.1 | I46: KG | J46: =IFERROR(VLOOKUP(F46,'Base Insumos'!$A:$C,3,FALSE()),"PENDENTE") | K46: =IFERROR(IF(J46="PENDENTE",0,J46*H46),0) | L46: 14.99 | M46: =IFERROR(K46/L46,0)
A47: Espetos | B47: Premium | C47: Tulipa | D47: =IF(ISERROR(VLOOKUP(E47,'Estrutura Protheus'!A:A,1,FALSE)),"Não","Sim") | E47: 001082 | F47: 000292 | G47: Espeto Tulipa | H47: 1 | I47: UN | J47: =IFERROR(VLOOKUP(F47,'Base Insumos'!$A:$C,3,FALSE()),"PENDENTE") | K47: =IFERROR(IF(J47="PENDENTE",0,J47*H47),0) | L47: 13.99 | M47: =IFERROR(K47/L47,0)
A48: Espetos | B48: In Natura | C48: Tulipa | D48: =IF(ISERROR(VLOOKUP(E48,'Estrutura Protheus'!A:A,1,FALSE)),"Não","Sim") | E48: 000010 | F48: 000292 | G48: Espeto Tulipa | H48: 5 | I48: UN | J48: =IFERROR(VLOOKUP(F48,'Base Insumos'!$A:$C,3,FALSE()),"PENDENTE") | K48: =IFERROR(IF(J48="PENDENTE",0,J48*H48),0) | L48: 29.9 | M48: =IFERROR(K48/L48,0)
A49: Espetos | B49: Espetos | C49: Dadinho de Tapioca | D49: =IF(ISERROR(VLOOKUP(E49,'Estrutura Protheus'!A:A,1,FALSE)),"Não","Sim") | E49: 001254 | F49: 001250 | G49: Dadinho de Tapioca 0,750gr | H49: 0.1 | I49: KG | J49: =IFERROR(VLOOKUP(F49,'Base Insumos'!$A:$C,3,FALSE()),"PENDENTE") | K49: =IFERROR(IF(J49="PENDENTE",0,J49*H49),0) | L49: 15.99 | M49: =IFERROR(K49/L49,0)
A50: Espetos | B50: Espetos | C50: Dadinho de Tapioca | D50: =IF(ISERROR(VLOOKUP(E50,'Estrutura Protheus'!A:A,1,FALSE)),"Não","Sim") | E50: 001254 | F50: 000440 | G50: Não Encontrado na Base | H50: 0.02 | J50: =IFERROR(VLOOKUP(F50,'Base Insumos'!$A:$C,3,FALSE()),"PENDENTE") | K50: =IFERROR(IF(J50="PENDENTE",0,J50*H50),0) | L50: 15.99 | M50: =IFERROR(K50/L50,0)
A51: Espetos | B51: Espetos | C51: Dadinho de Tapioca | D51: =IF(ISERROR(VLOOKUP(E51,'Estrutura Protheus'!A:A,1,FALSE)),"Não","Sim") | E51: 001254 | F51: 001251 | G51: Geleia de Pimenta 1,2kg | H51: 0.005 | I51: KG | J51: =IFERROR(VLOOKUP(F51,'Base Insumos'!$A:$C,3,FALSE()),"PENDENTE") | K51: =IFERROR(IF(J51="PENDENTE",0,J51*H51),0) | L51: 15.99 | M51: =IFERROR(K51/L51,0)
A52: Espetos | B52: Espetos | C52: Espeto de Alho Poró com Tomate Cereja | D52: =IF(ISERROR(VLOOKUP(E52,'Estrutura Protheus'!A:A,1,FALSE)),"Não","Sim") | E52: 002122 | F52: 002070 | G52: Alho Poro | H52: 0.1 | I52: KG | J52: =IFERROR(VLOOKUP(F52,'Base Insumos'!$A:$C,3,FALSE()),"PENDENTE") | K52: =IFERROR(IF(J52="PENDENTE",0,J52*H52),0) | L52: 12.99 | M52: =IFERROR(K52/L52,0)
A53: Espetos | B53: Espetos | C53: Espeto de Alho Poró com Tomate Cereja | D53: =IF(ISERROR(VLOOKUP(E53,'Estrutura Protheus'!A:A,1,FALSE)),"Não","Sim") | E53: 002122 | F53: 000485 | G53: Tomate Cereja | H53: 0.04 | I53: KG | J53: =IFERROR(VLOOKUP(F53,'Base Insumos'!$A:$C,3,FALSE()),"PENDENTE") | K53: =IFERROR(IF(J53="PENDENTE",0,J53*H53),0) | L53: 12.99 | M53: =IFERROR(K53/L53,0)
A54: Espetos | B54: Espetos | C54: Espeto de Berinjela no Shoyu | D54: =IF(ISERROR(VLOOKUP(E54,'Estrutura Protheus'!A:A,1,FALSE)),"Não","Sim") | E54: 002125 | F54: 000466 | G54: Berinjela | H54: 0.12 | I54: KG | J54: =IFERROR(VLOOKUP(F54,'Base Insumos'!$A:$C,3,FALSE()),"PENDENTE") | K54: =IFERROR(IF(J54="PENDENTE",0,J54*H54),0) | L54: 12.99 | M54: =IFERROR(K54/L54,0)
A55: Espetos | B55: Espetos | C55: Espeto de Mussarela de Búfala com Rucula e Tomate Seco | D55: =IF(ISERROR(VLOOKUP(E55,'Estrutura Protheus'!A:A,1,FALSE)),"Não","Sim") | E55: 000279 | F55: 000442 | G55: Mussarela de Bufala | H55: 0.07 | I55: KG | J55: =IFERROR(VLOOKUP(F55,'Base Insumos'!$A:$C,3,FALSE()),"PENDENTE") | K55: =IFERROR(IF(J55="PENDENTE",0,J55*H55),0) | L55: 14.99 | M55: =IFERROR(K55/L55,0)
A56: Espetos | B56: Espetos | C56: Espeto de Mussarela de Búfala com Rucula e Tomate Seco | D56: =IF(ISERROR(VLOOKUP(E56,'Estrutura Protheus'!A:A,1,FALSE)),"Não","Sim") | E56: 000279 | F56: 000440 | G56: Não Encontrado na Base | H56: 0.02 | J56: =IFERROR(VLOOKUP(F56,'Base Insumos'!$A:$C,3,FALSE()),"PENDENTE") | K56: =IFERROR(IF(J56="PENDENTE",0,J56*H56),0) | L56: 14.99 | M56: =IFERROR(K56/L56,0)
A57: Espetos | B57: Espetos | C57: Espeto de Mussarela de Búfala com Rucula e Tomate Seco | D57: =IF(ISERROR(VLOOKUP(E57,'Estrutura Protheus'!A:A,1,FALSE)),"Não","Sim") | E57: 000279 | F57: 000444 | G57: Tomate Seco | H57: 0.025 | I57: KG | J57: =IFERROR(VLOOKUP(F57,'Base Insumos'!$A:$C,3,FALSE()),"PENDENTE") | K57: =IFERROR(IF(J57="PENDENTE",0,J57*H57),0) | L57: 14.99 | M57: =IFERROR(K57/L57,0)
A58: Espetos | B58: Espetos | C58: Espeto de Pupunha com Tomate Seco e Rúcula | D58: =IF(ISERROR(VLOOKUP(E58,'Estrutura Protheus'!A:A,1,FALSE)),"Não","Sim") | E58: 000280 | F58: 000445 | G58: Tolete de Pupunha 1,8kg | H58: 0.09 | I58: KG | J58: =IFERROR(VLOOKUP(F58,'Base Insumos'!$A:$C,3,FALSE()),"PENDENTE") | K58: =IFERROR(IF(J58="PENDENTE",0,J58*H58),0) | L58: 18.99 | M58: =IFERROR(K58/L58,0)
A59: Espetos | B59: Espetos | C59: Espeto de Pupunha com Tomate Seco e Rúcula | D59: =IF(ISERROR(VLOOKUP(E59,'Estrutura Protheus'!A:A,1,FALSE)),"Não","Sim") | E59: 000280 | F59: 000407 | G59: Molho Salada Ervas Finas 236ml | H59: 0.01 | I59: UN | J59: =IFERROR(VLOOKUP(F59,'Base Insumos'!$A:$C,3,FALSE()),"PENDENTE") | K59: =IFERROR(IF(J59="PENDENTE",0,J59*H59),0) | L59: 18.99 | M59: =IFERROR(K59/L59,0)
A60: Espetos | B60: Espetos | C60: Espeto de Pupunha com Tomate Seco e Rúcula | D60: =IF(ISERROR(VLOOKUP(E60,'Estrutura Protheus'!A:A,1,FALSE)),"Não","Sim") | E60: 000280 | F60: 000444 | G60: Tomate Seco | H60: 0.025 | I60: KG | J60: =IFERROR(VLOOKUP(F60,'Base Insumos'!$A:$C,3,FALSE()),"PENDENTE") | K60: =IFERROR(IF(J60="PENDENTE",0,J60*H60),0) | L60: 18.99 | M60: =IFERROR(K60/L60,0)
A61: Espetos | B61: Espetos | C61: Espeto de Pupunha com Tomate Seco e Rúcula | D61: =IF(ISERROR(VLOOKUP(E61,'Estrutura Protheus'!A:A,1,FALSE)),"Não","Sim") | E61: 000280 | F61: 000483 | G61: Rucula Hidroponica | H61: 0.01 | I61: KG | J61: =IFERROR(VLOOKUP(F61,'Base Insumos'!$A:$C,3,FALSE()),"PENDENTE") | K61: =IFERROR(IF(J61="PENDENTE",0,J61*H61),0) | L61: 18.99 | M61: =IFERROR(K61/L61,0)
A62: Espetos | B62: Espetos | C62: Pupunha na Brasa | D62: =IF(ISERROR(VLOOKUP(E62,'Estrutura Protheus'!A:A,1,FALSE)),"Não","Sim") | E62: 001070 | F62: 000445 | G62: Tolete de Pupunha 1,8kg | H62: 0.11 | I62: KG | J62: =IFERROR(VLOOKUP(F62,'Base Insumos'!$A:$C,3,FALSE()),"PENDENTE") | K62: =IFERROR(IF(J62="PENDENTE",0,J62*H62),0) | L62: 16.99 | M62: =IFERROR(K62/L62,0)
A63: Espetos | B63: Espetos | C63: Pupunha na Brasa | D63: =IF(ISERROR(VLOOKUP(E63,'Estrutura Protheus'!A:A,1,FALSE)),"Não","Sim") | E63: 001070 | F63: 000667 | G63: Tomilho | H63: 0.005 | I63: KG | J63: =IFERROR(VLOOKUP(F63,'Base Insumos'!$A:$C,3,FALSE()),"PENDENTE") | K63: =IFERROR(IF(J63="PENDENTE",0,J63*H63),0) | L63: 16.99 | M63: =IFERROR(K63/L63,0)
A64: Espetos | B64: Espetos | C64: Pupunha na Brasa | D64: =IF(ISERROR(VLOOKUP(E64,'Estrutura Protheus'!A:A,1,FALSE)),"Não","Sim") | E64: 001070 | F64: 000614 | G64: Sal Refinado | H64: 0.0008 | I64: KG | J64: =IFERROR(VLOOKUP(F64,'Base Insumos'!$A:$C,3,FALSE()),"PENDENTE") | K64: =IFERROR(IF(J64="PENDENTE",0,J64*H64),0) | L64: 16.99 | M64: =IFERROR(K64/L64,0)
A65: Espetos | B65: Espetos | C65: Ratatouile no Espeto | D65: =IF(ISERROR(VLOOKUP(E65,'Estrutura Protheus'!A:A,1,FALSE)),"Não","Sim") | E65: 002123 | F65: 000753 | G65: Cebola Roxa | H65: 0.05 | I65: KG | J65: =IFERROR(VLOOKUP(F65,'Base Insumos'!$A:$C,3,FALSE()),"PENDENTE") | K65: =IFERROR(IF(J65="PENDENTE",0,J65*H65),0) | L65: 11.9 | M65: =IFERROR(K65/L65,0)
A66: Espetos | B66: Espetos | C66: Ratatouile no Espeto | D66: =IF(ISERROR(VLOOKUP(E66,'Estrutura Protheus'!A:A,1,FALSE)),"Não","Sim") | E66: 002123 | F66: 000486 | G66: Tomate Salada | H66: 0.025 | I66: KG | J66: =IFERROR(VLOOKUP(F66,'Base Insumos'!$A:$C,3,FALSE()),"PENDENTE") | K66: =IFERROR(IF(J66="PENDENTE",0,J66*H66),0) | L66: 11.9 | M66: =IFERROR(K66/L66,0)
A67: Espetos | B67: Espetos | C67: Ratatouile no Espeto | D67: =IF(ISERROR(VLOOKUP(E67,'Estrutura Protheus'!A:A,1,FALSE)),"Não","Sim") | E67: 002123 | F67: 000459 | G67: Abobrinha Italiana | H67: 0.025 | I67: KG | J67: =IFERROR(VLOOKUP(F67,'Base Insumos'!$A:$C,3,FALSE()),"PENDENTE") | K67: =IFERROR(IF(J67="PENDENTE",0,J67*H67),0) | L67: 11.9 | M67: =IFERROR(K67/L67,0)
A68: Espetos | B68: Espetos | C68: Ratatouile no Espeto | D68: =IF(ISERROR(VLOOKUP(E68,'Estrutura Protheus'!A:A,1,FALSE)),"Não","Sim") | E68: 002123 | F68: 000617 | G68: Pimentao Amarelo | H68: 0.025 | I68: KG | J68: =IFERROR(VLOOKUP(F68,'Base Insumos'!$A:$C,3,FALSE()),"PENDENTE") | K68: =IFERROR(IF(J68="PENDENTE",0,J68*H68),0) | L68: 11.9 | M68: =IFERROR(K68/L68,0)
...

Sheet CMV Consolidado
A1: Identificação | F1: Semana Atual | L1: Semana Anterior | R1: Análise
A2: Categoria | B2: Subcategoria | C2: Item | D2: Nome da PA no Protheus | E2: Código PA | F2: Preço Venda (R$) | G2: Custo CMV (R$) | H2: CMV (%) | I2: Marg. Contrib. (R$) | J2: Marg. Contrib. (%) | K2: Preço Sugerido CMV 30% | L2: Preço Venda (R$) | M2: Custo CMV (R$) | N2: CMV (%) | O2: Marg. Contrib. (R$) | P2: Marg. Contrib. (%) | Q2: Data Ref. | R2: Variação CMV % | S2: No Cardápio Digital | T2: Status | U2: Ação | V2: Observação
A3: Bebidas Frias | B3: Vodka | C3: Absolut | D3: =VLOOKUP(E3,_Protheus_Cadastro!A:I,2,FALSE) | E3: 000049 | F3: =IFERROR(INDEX(Vendidos!$H:$H,MATCH(E3,Vendidos!$B:$B,0)),"—") | G3: =SUMIF('Fichas Flat'!$E$2:$E$880,E3,'Fichas Flat'!$K$2:$K$880) | H3: =IFERROR(G3/F3,0) | I3: =IFERROR(F3-G3,0) | J3: =IFERROR(I3/F3,0) | K3: =IFERROR(G3/0.3,0) | L3: PENDENTE | M3: 106.89997 | N3: - | O3: - | P3: - | Q3: 46148 | R3: =IFERROR(IF(M3="","—",H3-N3),"—") | S3: Sim | T3: =IFERROR(IF(H3=0,"—",IF(H3<=0.25,"✔ OK",IF(H3<=0.35,"⚠ Atenção","✖ Crítico"))),"—")
A4: Drinks | B4: Drinks | C4: Maracujack | D4: =VLOOKUP(E4,_Protheus_Cadastro!A:I,2,FALSE) | E4: 001202 | F4: =IFERROR(INDEX(Vendidos!$H:$H,MATCH(E4,Vendidos!$B:$B,0)),"—") | G4: =SUMIF('Fichas Flat'!$E$2:$E$880,E4,'Fichas Flat'!$K$2:$K$880) | H4: =IFERROR(G4/F4,0) | I4: =IFERROR(F4-G4,0) | J4: =IFERROR(I4/F4,0) | K4: =IFERROR(G4/0.3,0) | L4: PENDENTE | M4: 8.2542 | N4: - | O4: - | P4: - | Q4: 46148 | R4: =IFERROR(IF(M4="","—",H4-N4),"—") | S4: Não | T4: =IFERROR(IF(H4=0,"—",IF(H4<=0.25,"✔ OK",IF(H4<=0.35,"⚠ Atenção","✖ Crítico"))),"—")
A5: Bebidas Frias | B5: Bebidas Prontas | C5: Beats Senses | D5: =VLOOKUP(E5,_Protheus_Cadastro!A:I,2,FALSE) | E5: 001336 | F5: =IFERROR(INDEX(Vendidos!$H:$H,MATCH(E5,Vendidos!$B:$B,0)),"—") | G5: =SUMIF('Fichas Flat'!$E$2:$E$880,E5,'Fichas Flat'!$K$2:$K$880) | H5: =IFERROR(G5/F5,0) | I5: =IFERROR(F5-G5,0) | J5: =IFERROR(I5/F5,0) | K5: =IFERROR(G5/0.3,0) | L5: PENDENTE | M5: 230.90002 | N5: - | O5: - | P5: - | Q5: 46148 | R5: =IFERROR(IF(M5="","—",H5-N5),"—") | S5: Não | T5: =IFERROR(IF(H5=0,"—",IF(H5<=0.25,"✔ OK",IF(H5<=0.35,"⚠ Atenção","✖ Crítico"))),"—")
A6: Espetos | B6: Veggie | C6: Espeto de Brócolis com Couve Flor | D6: =VLOOKUP(E6,_Protheus_Cadastro!A:I,2,FALSE) | E6: PENDENTE | F6: =IFERROR(INDEX(Vendidos!$H:$H,MATCH(E6,Vendidos!$B:$B,0)),"—") | G6: =SUMIF('Fichas Flat'!$E$2:$E$880,E6,'Fichas Flat'!$K$2:$K$880) | H6: =IFERROR(G6/F6,0) | I6: =IFERROR(F6-G6,0) | J6: =IFERROR(I6/F6,0) | K6: =IFERROR(G6/0.3,0) | Q6: 46148 | R6: =IFERROR(IF(M6="","—",H6-N6),"—") | S6: Não | T6: =IFERROR(IF(H6=0,"—",IF(H6<=0.25,"✔ OK",IF(H6<=0.35,"⚠ Atenção","✖ Crítico"))),"—")
A7: Espetos | B7: Veggie | C7: Espeto de Mix de Legumes | D7: =VLOOKUP(E7,_Protheus_Cadastro!A:I,2,FALSE) | E7: PENDENTE | F7: =IFERROR(INDEX(Vendidos!$H:$H,MATCH(E7,Vendidos!$B:$B,0)),"—") | G7: =SUMIF('Fichas Flat'!$E$2:$E$880,E7,'Fichas Flat'!$K$2:$K$880) | H7: =IFERROR(G7/F7,0) | I7: =IFERROR(F7-G7,0) | J7: =IFERROR(I7/F7,0) | K7: =IFERROR(G7/0.3,0) | Q7: 46148 | R7: =IFERROR(IF(M7="","—",H7-N7),"—") | S7: Não | T7: =IFERROR(IF(H7=0,"—",IF(H7<=0.25,"✔ OK",IF(H7<=0.35,"⚠ Atenção","✖ Crítico"))),"—")
A8: Espetos | B8: Veggie | C8: Espeto de Queijo Coalho com Abobrinha | D8: =VLOOKUP(E8,_Protheus_Cadastro!A:I,2,FALSE) | E8: PENDENTE | F8: =IFERROR(INDEX(Vendidos!$H:$H,MATCH(E8,Vendidos!$B:$B,0)),"—") | G8: =SUMIF('Fichas Flat'!$E$2:$E$880,E8,'Fichas Flat'!$K$2:$K$880) | H8: =IFERROR(G8/F8,0) | I8: =IFERROR(F8-G8,0) | J8: =IFERROR(I8/F8,0) | K8: =IFERROR(G8/0.3,0) | Q8: 46148 | R8: =IFERROR(IF(M8="","—",H8-N8),"—") | S8: Sim | T8: =IFERROR(IF(H8=0,"—",IF(H8<=0.25,"✔ OK",IF(H8<=0.35,"⚠ Atenção","✖ Crítico"))),"—")
A9: Bebidas Frias | B9: Gin | C9: Gin Bacco Quintal 700ml | D9: =VLOOKUP(E9,_Protheus_Cadastro!A:I,2,FALSE) | E9: 010011 | F9: =IFERROR(INDEX(Vendidos!$H:$H,MATCH(E9,Vendidos!$B:$B,0)),"—") | G9: =SUMIF('Fichas Flat'!$E$2:$E$880,E9,'Fichas Flat'!$K$2:$K$880) | H9: =IFERROR(G9/F9,0) | I9: =IFERROR(F9-G9,0) | J9: =IFERROR(I9/F9,0) | K9: =IFERROR(G9/0.3,0) | L9: PENDENTE | M9: 5.4277 | N9: - | O9: - | P9: - | Q9: 46148 | R9: =IFERROR(IF(M9="","—",H9-N9),"—") | S9: Não | T9: =IFERROR(IF(H9=0,"—",IF(H9<=0.25,"✔ OK",IF(H9<=0.35,"⚠ Atenção","✖ Crítico"))),"—")
A10: Bebidas Frias | B10: Vodka | C10: Vodka Bacco Quintal 1LT | D10: =VLOOKUP(E10,_Protheus_Cadastro!A:I,2,FALSE) | E10: 010012 | F10: =IFERROR(INDEX(Vendidos!$H:$H,MATCH(E10,Vendidos!$B:$B,0)),"—") | G10: =SUMIF('Fichas Flat'!$E$2:$E$880,E10,'Fichas Flat'!$K$2:$K$880) | H10: =IFERROR(G10/F10,0) | I10: =IFERROR(F10-G10,0) | J10: =IFERROR(I10/F10,0) | K10: =IFERROR(G10/0.3,0) | L10: PENDENTE | M10: 37.24 | N10: - | O10: - | P10: - | Q10: 46148 | R10: =IFERROR(IF(M10="","—",H10-N10),"—") | S10: Não | T10: =IFERROR(IF(H10=0,"—",IF(H10<=0.25,"✔ OK",IF(H10<=0.35,"⚠ Atenção","✖ Crítico"))),"—")
A11: Saladas e Molhos | B11: Saladas | C11: Salada Caprese | D11: =VLOOKUP(E11,_Protheus_Cadastro!A:I,2,FALSE) | E11: 000869 | F11: =IFERROR(INDEX(Vendidos!$H:$H,MATCH(E11,Vendidos!$B:$B,0)),"—") | G11: =SUMIF('Fichas Flat'!$E$2:$E$880,E11,'Fichas Flat'!$K$2:$K$880) | H11: =IFERROR(G11/F11,0) | I11: =IFERROR(F11-G11,0) | J11: =IFERROR(I11/F11,0) | K11: =IFERROR(G11/0.3,0) | Q11: 46148 | R11: =IFERROR(IF(M11="","—",H11-N11),"—") | S11: Sim | T11: =IFERROR(IF(H11=0,"—",IF(H11<=0.25,"✔ OK",IF(H11<=0.35,"⚠ Atenção","✖ Crítico"))),"—")
A12: Saladas e Molhos | B12: Saladas | C12: Salada da Casa | D12: =VLOOKUP(E12,_Protheus_Cadastro!A:I,2,FALSE) | E12: 000870 | F12: =IFERROR(INDEX(Vendidos!$H:$H,MATCH(E12,Vendidos!$B:$B,0)),"—") | G12: =SUMIF('Fichas Flat'!$E$2:$E$880,E12,'Fichas Flat'!$K$2:$K$880) | H12: =IFERROR(G12/F12,0) | I12: =IFERROR(F12-G12,0) | J12: =IFERROR(I12/F12,0) | K12: =IFERROR(G12/0.3,0) | Q12: 46148 | R12: =IFERROR(IF(M12="","—",H12-N12),"—") | S12: Sim | T12: =IFERROR(IF(H12=0,"—",IF(H12<=0.25,"✔ OK",IF(H12<=0.35,"⚠ Atenção","✖ Crítico"))),"—")
A13: Saladas e Molhos | B13: Saladas | C13: Salada Juliana | D13: =VLOOKUP(E13,_Protheus_Cadastro!A:I,2,FALSE) | E13: 000871 | F13: =IFERROR(INDEX(Vendidos!$H:$H,MATCH(E13,Vendidos!$B:$B,0)),"—") | G13: =SUMIF('Fichas Flat'!$E$2:$E$880,E13,'Fichas Flat'!$K$2:$K$880) | H13: =IFERROR(G13/F13,0) | I13: =IFERROR(F13-G13,0) | J13: =IFERROR(I13/F13,0) | K13: =IFERROR(G13/0.3,0) | Q13: 46148 | R13: =IFERROR(IF(M13="","—",H13-N13),"—") | S13: Sim | T13: =IFERROR(IF(H13=0,"—",IF(H13<=0.25,"✔ OK",IF(H13<=0.35,"⚠ Atenção","✖ Crítico"))),"—")
A14: Saladas e Molhos | B14: Saladas | C14: Salada California | D14: =VLOOKUP(E14,_Protheus_Cadastro!A:I,2,FALSE) | E14: 002215 | F14: =IFERROR(INDEX(Vendidos!$H:$H,MATCH(E14,Vendidos!$B:$B,0)),"—") | G14: =SUMIF('Fichas Flat'!$E$2:$E$880,E14,'Fichas Flat'!$K$2:$K$880) | H14: =IFERROR(G14/F14,0) | I14: =IFERROR(F14-G14,0) | J14: =IFERROR(I14/F14,0) | K14: =IFERROR(G14/0.3,0) | Q14: 46148 | R14: =IFERROR(IF(M14="","—",H14-N14),"—") | S14: Não | T14: =IFERROR(IF(H14=0,"—",IF(H14<=0.25,"✔ OK",IF(H14<=0.35,"⚠ Atenção","✖ Crítico"))),"—")
A15: Saladas e Molhos | B15: Saladas | C15: Mini Salada Quintal | D15: =VLOOKUP(E15,_Protheus_Cadastro!A:I,2,FALSE) | E15: 002262 | F15: =IFERROR(INDEX(Vendidos!$H:$H,MATCH(E15,Vendidos!$B:$B,0)),"—") | G15: =SUMIF('Fichas Flat'!$E$2:$E$880,E15,'Fichas Flat'!$K$2:$K$880) | H15: =IFERROR(G15/F15,0) | I15: =IFERROR(F15-G15,0) | J15: =IFERROR(I15/F15,0) | K15: =IFERROR(G15/0.3,0) | Q15: 46148 | R15: =IFERROR(IF(M15="","—",H15-N15),"—") | S15: Não | T15: =IFERROR(IF(H15=0,"—",IF(H15<=0.25,"✔ OK",IF(H15<=0.35,"⚠ Atenção","✖ Crítico"))),"—")
A16: Saladas e Molhos | B16: Saladas | C16: Mini Salada Fresca | D16: =IFERROR(VLOOKUP(E16,_Protheus_Cadastro!$A:$B,2,FALSE),"—") | E16: 002239 | F16: =IFERROR(INDEX(Vendidos!$H:$H,MATCH(E16,Vendidos!$B:$B,0)),"—") | G16: =SUMIF('Fichas Flat'!$E$2:$E$880,E16,'Fichas Flat'!$K$2:$K$880) | H16: =IFERROR(G16/F16,0) | I16: =IFERROR(F16-G16,0) | J16: =IFERROR(I16/F16,0) | K16: =IFERROR(G16/0.3,0) | R16: =IFERROR(IF(G16=0,"—",IF(H16<=0.25,"✔ OK",IF(H16<=0.35,"⚠ Atenção","✖ Crítico"))),"—") | S16: Não
A17: Cardápio Principal | B17: Sazonais | C17: Caldo de Feijão | D17: =VLOOKUP(E17,_Protheus_Cadastro!A:I,2,FALSE) | E17: 001340 | F17: =IFERROR(INDEX(Vendidos!$H:$H,MATCH(E17,Vendidos!$B:$B,0)),"—") | G17: =SUMIF('Fichas Flat'!$E$2:$E$880,E17,'Fichas Flat'!$K$2:$K$880) | H17: =IFERROR(G17/F17,0) | I17: =IFERROR(F17-G17,0) | J17: =IFERROR(I17/F17,0) | K17: =IFERROR(G17/0.3,0) | Q17: 46148 | R17: =IFERROR(IF(M16="","—",H17-N16),"—") | S17: Sim | T17: =IFERROR(IF(H16=0,"—",IF(H16<=0.25,"✔ OK",IF(H16<=0.35,"⚠ Atenção","✖ Crítico"))),"—")
A18: Saladas e Molhos | B18: Sazonais | C18: Caldo Verde | D18: =VLOOKUP(E18,_Protheus_Cadastro!A:I,2,FALSE) | E18: 001341 | F18: =IFERROR(INDEX(Vendidos!$H:$H,MATCH(E18,Vendidos!$B:$B,0)),"—") | G18: =SUMIF('Fichas Flat'!$E$2:$E$880,E18,'Fichas Flat'!$K$2:$K$880) | H18: =IFERROR(G18/F18,0) | I18: =IFERROR(F18-G18,0) | J18: =IFERROR(I18/F18,0) | K18: =IFERROR(G18/0.3,0) | Q18: 46148 | R18: =IFERROR(IF(M17="","—",H18-N17),"—") | S18: Sim | T18: =IFERROR(IF(H17=0,"—",IF(H17<=0.25,"✔ OK",IF(H17<=0.35,"⚠ Atenção","✖ Crítico"))),"—")
A19: Saladas e Molhos | B19: Sazonais | C19: Vinho Quente | D19: =VLOOKUP(E19,_Protheus_Cadastro!A:I,2,FALSE) | E19: 001076 | F19: =IFERROR(INDEX(Vendidos!$H:$H,MATCH(E19,Vendidos!$B:$B,0)),"—") | G19: =SUMIF('Fichas Flat'!$E$2:$E$880,E19,'Fichas Flat'!$K$2:$K$880) | H19: =IFERROR(G19/F19,0) | I19: =IFERROR(F19-G19,0) | J19: =IFERROR(I19/F19,0) | K19: =IFERROR(G19/0.3,0) | Q19: 46148 | R19: =IFERROR(IF(M18="","—",H19-N18),"—") | S19: Sim | T19: =IFERROR(IF(H18=0,"—",IF(H18<=0.25,"✔ OK",IF(H18<=0.35,"⚠ Atenção","✖ Crítico"))),"—")
A20: Saladas e Molhos | B20: Molhos | C20: Chimichurri do Quintal | D20: =VLOOKUP(E20,_Protheus_Cadastro!A:I,2,FALSE) | E20: PENDENTE | F20: =IFERROR(INDEX(Vendidos!$H:$H,MATCH(E20,Vendidos!$B:$B,0)),"—") | G20: =SUMIF('Fichas Flat'!$E$2:$E$880,E20,'Fichas Flat'!$K$2:$K$880) | H20: =IFERROR(G20/F20,0) | I20: =IFERROR(F20-G20,0) | J20: =IFERROR(I20/F20,0) | K20: =IFERROR(G20/0.3,0) | Q20: 46148 | R20: =IFERROR(IF(M19="","—",H20-N19),"—") | S20: Não | T20: =IFERROR(IF(H19=0,"—",IF(H19<=0.25,"✔ OK",IF(H19<=0.35,"⚠ Atenção","✖ Crítico"))),"—")
A21: Saladas e Molhos | B21: Molhos | C21: Geleia de Pimenta | D21: =VLOOKUP(E21,_Protheus_Cadastro!A:I,2,FALSE) | E21: PENDENTE | F21: =IFERROR(INDEX(Vendidos!$H:$H,MATCH(E21,Vendidos!$B:$B,0)),"—") | G21: =SUMIF('Fichas Flat'!$E$2:$E$880,E21,'Fichas Flat'!$K$2:$K$880) | H21: =IFERROR(G21/F21,0) | I21: =IFERROR(F21-G21,0) | J21: =IFERROR(I21/F21,0) | K21: =IFERROR(G21/0.3,0) | Q21: 46148 | R21: =IFERROR(IF(M20="","—",H21-N20),"—") | S21: Não | T21: =IFERROR(IF(H20=0,"—",IF(H20<=0.25,"✔ OK",IF(H20<=0.35,"⚠ Atenção","✖ Crítico"))),"—")
A22: Saladas e Molhos | B22: Molhos | C22: Maionese de Alho e Sal Quintal | D22: =VLOOKUP(E22,_Protheus_Cadastro!A:I,2,FALSE) | E22: PENDENTE | F22: =IFERROR(INDEX(Vendidos!$H:$H,MATCH(E22,Vendidos!$B:$B,0)),"—") | G22: =SUMIF('Fichas Flat'!$E$2:$E$880,E22,'Fichas Flat'!$K$2:$K$880) | H22: =IFERROR(G22/F22,0) | I22: =IFERROR(F22-G22,0) | J22: =IFERROR(I22/F22,0) | K22: =IFERROR(G22/0.3,0) | Q22: 46148 | R22: =IFERROR(IF(M21="","—",H22-N21),"—") | S22: Não | T22: =IFERROR(IF(H21=0,"—",IF(H21<=0.25,"✔ OK",IF(H21<=0.35,"⚠ Atenção","✖ Crítico"))),"—")
A23: Saladas e Molhos | B23: Molhos | C23: Molho Pesto | D23: =VLOOKUP(E23,_Protheus_Cadastro!A:I,2,FALSE) | E23: PENDENTE | F23: =IFERROR(INDEX(Vendidos!$H:$H,MATCH(E23,Vendidos!$B:$B,0)),"—") | G23: =SUMIF('Fichas Flat'!$E$2:$E$880,E23,'Fichas Flat'!$K$2:$K$880) | H23: =IFERROR(G23/F23,0) | I23: =IFERROR(F23-G23,0) | J23: =IFERROR(I23/F23,0) | K23: =IFERROR(G23/0.3,0) | Q23: 46148 | R23: =IFERROR(IF(M22="","—",H23-N22),"—") | S23: Não | T23: =IFERROR(IF(H22=0,"—",IF(H22<=0.25,"✔ OK",IF(H22<=0.35,"⚠ Atenção","✖ Crítico"))),"—")
A24: Saladas e Molhos | B24: Molhos | C24: Molho Mostarda e Mel | D24: =VLOOKUP(E24,_Protheus_Cadastro!A:I,2,FALSE) | E24: PENDENTE | F24: =IFERROR(INDEX(Vendidos!$H:$H,MATCH(E24,Vendidos!$B:$B,0)),"—") | G24: =SUMIF('Fichas Flat'!$E$2:$E$880,E24,'Fichas Flat'!$K$2:$K$880) | H24: =IFERROR(G24/F24,0) | I24: =IFERROR(F24-G24,0) | J24: =IFERROR(I24/F24,0) | K24: =IFERROR(G24/0.3,0) | Q24: 46148 | R24: =IFERROR(IF(M23="","—",H24-N23),"—") | S24: Não | T24: =IFERROR(IF(H23=0,"—",IF(H23<=0.25,"✔ OK",IF(H23<=0.35,"⚠ Atenção","✖ Crítico"))),"—")
A25: Saladas e Molhos | B25: Molhos | C25: Molho de Hortelã | D25: =VLOOKUP(E25,_Protheus_Cadastro!A:I,2,FALSE) | E25: PENDENTE | F25: =IFERROR(INDEX(Vendidos!$H:$H,MATCH(E25,Vendidos!$B:$B,0)),"—") | G25: =SUMIF('Fichas Flat'!$E$2:$E$880,E25,'Fichas Flat'!$K$2:$K$880) | H25: =IFERROR(G25/F25,0) | I25: =IFERROR(F25-G25,0) | J25: =IFERROR(I25/F25,0) | K25: =IFERROR(G25/0.3,0) | Q25: 46148 | R25: =IFERROR(IF(M24="","—",H25-N24),"—") | S25: Sim | T25: =IFERROR(IF(H24=0,"—",IF(H24<=0.25,"✔ OK",IF(H24<=0.35,"⚠ Atenção","✖ Crítico"))),"—")
A26: Saladas e Molhos | B26: Molhos | C26: Molho Azeite de Ervas | D26: =VLOOKUP(E26,_Protheus_Cadastro!A:I,2,FALSE) | E26: PENDENTE | F26: =IFERROR(INDEX(Vendidos!$H:$H,MATCH(E26,Vendidos!$B:$B,0)),"—") | G26: =SUMIF('Fichas Flat'!$E$2:$E$880,E26,'Fichas Flat'!$K$2:$K$880) | H26: =IFERROR(G26/F26,0) | I26: =IFERROR(F26-G26,0) | J26: =IFERROR(I26/F26,0) | K26: =IFERROR(G26/0.3,0) | Q26: 46148 | R26: =IFERROR(IF(M25="","—",H26-N25),"—") | S26: Não | T26: =IFERROR(IF(H25=0,"—",IF(H25<=0.25,"✔ OK",IF(H25<=0.35,"⚠ Atenção","✖ Crítico"))),"—")
A27: Saladas e Molhos | B27: Molhos | C27: Molho Manteiga | D27: =VLOOKUP(E27,_Protheus_Cadastro!A:I,2,FALSE) | E27: PENDENTE | F27: =IFERROR(INDEX(Vendidos!$H:$H,MATCH(E27,Vendidos!$B:$B,0)),"—") | G27: =SUMIF('Fichas Flat'!$E$2:$E$880,E27,'Fichas Flat'!$K$2:$K$880) | H27: =IFERROR(G27/F27,0) | I27: =IFERROR(F27-G27,0) | J27: =IFERROR(I27/F27,0) | K27: =IFERROR(G27/0.3,0) | Q27: 46148 | R27: =IFERROR(IF(M26="","—",H27-N26),"—") | S27: Não | T27: =IFERROR(IF(H26=0,"—",IF(H26<=0.25,"✔ OK",IF(H26<=0.35,"⚠ Atenção","✖ Crítico"))),"—")
A28: Drinks | B28: Drinks | C28: Soda italiana - Maracujá | D28: =VLOOKUP(E28,_Protheus_Cadastro!A:I,2,FALSE) | E28: 010314 | F28: =IFERROR(INDEX(Vendidos!$H:$H,MATCH(E28,Vendidos!$B:$B,0)),"—") | G28: =SUMIF('Fichas Flat'!$E$2:$E$880,E28,'Fichas Flat'!$K$2:$K$880) | H28: =IFERROR(G28/F28,0) | I28: =IFERROR(F28-G28,0) | J28: =IFERROR(I28/F28,0) | K28: =IFERROR(G28/0.3,0) | L28: 16.99 | M28: 1.0778 | N28: 0.063437316 | O28: 15.9122 | P28: 0.93656268 | Q28: 46148 | R28: =IFERROR(IF(M11="","—",H11-N11),"—") | S28: Não | T28: =IFERROR(IF(H11=0,"—",IF(H11<=0.25,"✔ OK",IF(H11<=0.35,"⚠ Atenção","✖ Crítico"))),"—")
A29: Drinks | B29: Drinks | C29: Soda italiana - Limão Siciliano | D29: =VLOOKUP(E29,_Protheus_Cadastro!A:I,2,FALSE) | E29: 010315 | F29: =IFERROR(INDEX(Vendidos!$H:$H,MATCH(E29,Vendidos!$B:$B,0)),"—") | G29: =SUMIF('Fichas Flat'!$E$2:$E$880,E29,'Fichas Flat'!$K$2:$K$880) | H29: =IFERROR(G29/F29,0) | I29: =IFERROR(F29-G29,0) | J29: =IFERROR(I29/F29,0) | K29: =IFERROR(G29/0.3,0) | L29: 16.99 | M29: 13.633278 | N29: 0.80242955 | O29: 3.356722 | P29: 0.19757045 | Q29: 46148 | R29: =IFERROR(IF(M12="","—",H12-N12),"—") | S29: Não | T29: =IFERROR(IF(H12=0,"—",IF(H12<=0.25,"✔ OK",IF(H12<=0.35,"⚠ Atenção","✖ Crítico"))),"—")
A30: Drinks | B30: Drinks | C30: Jack Fire Ginger | D30: =VLOOKUP(E30,_Protheus_Cadastro!A:I,2,FALSE) | E30: 001324 | F30: =IFERROR(INDEX(Vendidos!$H:$H,MATCH(E30,Vendidos!$B:$B,0)),"—") | G30: =SUMIF('Fichas Flat'!$E$2:$E$880,E30,'Fichas Flat'!$K$2:$K$880) | H30: =IFERROR(G30/F30,0) | I30: =IFERROR(F30-G30,0) | J30: =IFERROR(I30/F30,0) | K30: =IFERROR(G30/0.3,0) | Q30: 46148 | R30: =IFERROR(IF(M29="","—",H30-N29),"—") | S30: Não | T30: =IFERROR(IF(H29=0,"—",IF(H29<=0.25,"✔ OK",IF(H29<=0.35,"⚠ Atenção","✖ Crítico"))),"—")
A31: Drinks | B31: Drinks | C31: Jack Honey e Lemonade | D31: =VLOOKUP(E31,_Protheus_Cadastro!A:I,2,FALSE) | E31: PENDENTE | F31: =IFERROR(INDEX(Vendidos!$H:$H,MATCH(E31,Vendidos!$B:$B,0)),"—") | G31: =SUMIF('Fichas Flat'!$E$2:$E$880,E31,'Fichas Flat'!$K$2:$K$880) | H31: =IFERROR(G31/F31,0) | I31: =IFERROR(F31-G31,0) | J31: =IFERROR(I31/F31,0) | K31: =IFERROR(G31/0.3,0) | Q31: 46148 | R31: =IFERROR(IF(M30="","—",H31-N30),"—") | S31: Não | T31: =IFERROR(IF(H30=0,"—",IF(H30<=0.25,"✔ OK",IF(H30<=0.35,"⚠ Atenção","✖ Crítico"))),"—")
A32: Drinks | B32: Drinks | C32: Gin Tônica Maça Verde | D32: =VLOOKUP(E32,_Protheus_Cadastro!A:I,2,FALSE) | E32: 001966 | F32: =IFERROR(INDEX(Vendidos!$H:$H,MATCH(E32,Vendidos!$B:$B,0)),"—") | G32: =SUMIF('Fichas Flat'!$E$2:$E$880,E32,'Fichas Flat'!$K$2:$K$880) | H32: =IFERROR(G32/F32,0) | I32: =IFERROR(F32-G32,0) | J32: =IFERROR(I32/F32,0) | K32: =IFERROR(G32/0.3,0) | Q32: 46148 | R32: =IFERROR(IF(M13="","—",H13-N13),"—") | S32: Não | T32: =IFERROR(IF(H13=0,"—",IF(H13<=0.25,"✔ OK",IF(H13<=0.35,"⚠ Atenção","✖ Crítico"))),"—")
A33: Drinks | B33: Sucos | C33: Jarra Suco de Maracujá | D33: =VLOOKUP(E33,_Protheus_Cadastro!A:I,2,FALSE) | E33: 002029 | F33: =IFERROR(INDEX(Vendidos!$H:$H,MATCH(E33,Vendidos!$B:$B,0)),"—") | G33: =SUMIF('Fichas Flat'!$E$2:$E$880,E33,'Fichas Flat'!$K$2:$K$880) | H33: =IFERROR(G33/F33,0) | I33: =IFERROR(F33-G33,0) | J33: =IFERROR(I33/F33,0) | K33: =IFERROR(G33/0.3,0) | Q33: 46148 | R33: =IFERROR(IF(M14="","—",H14-N14),"—") | S33: Não | T33: =IFERROR(IF(H14=0,"—",IF(H14<=0.25,"✔ OK",IF(H14<=0.35,"⚠ Atenção","✖ Crítico"))),"—")
A34: Drinks | B34: Sucos | C34: Jarra Suco de Laranja | D34: =VLOOKUP(E34,_Protheus_Cadastro!A:I,2,FALSE) | E34: 002026 | F34: =IFERROR(INDEX(Vendidos!$H:$H,MATCH(E34,Vendidos!$B:$B,0)),"—") | G34: =SUMIF('Fichas Flat'!$E$2:$E$880,E34,'Fichas Flat'!$K$2:$K$880) | H34: =IFERROR(G34/F34,0) | I34: =IFERROR(F34-G34,0) | J34: =IFERROR(I34/F34,0) | K34: =IFERROR(G34/0.3,0) | Q34: 46148 | R34: =IFERROR(IF(M15="","—",H15-N15),"—") | S34: Não | T34: =IFERROR(IF(H15=0,"—",IF(H15<=0.25,"✔ OK",IF(H15<=0.35,"⚠ Atenção","✖ Crítico"))),"—")
A35: Drinks | B35: Sucos | C35: Jarra Suco de Limão | D35: =VLOOKUP(E35,_Protheus_Cadastro!A:I,2,FALSE) | E35: 002028 | F35: =IFERROR(INDEX(Vendidos!$H:$H,MATCH(E35,Vendidos!$B:$B,0)),"—") | G35: =SUMIF('Fichas Flat'!$E$2:$E$880,E35,'Fichas Flat'!$K$2:$K$880) | H35: =IFERROR(G35/F35,0) | I35: =IFERROR(F35-G35,0) | J35: =IFERROR(I35/F35,0) | K35: =IFERROR(G35/0.3,0) | Q35: 46148 | R35: =IFERROR(IF(M16="","—",H16-N16),"—") | S35: Não | T35: =IFERROR(IF(H16=0,"—",IF(H16<=0.25,"✔ OK",IF(H16<=0.35,"⚠ Atenção","✖ Crítico"))),"—")
A36: Drinks | B36: Sucos | C36: Jarra Suco de Morango | D36: =VLOOKUP(E36,_Protheus_Cadastro!A:I,2,FALSE) | E36: 002031 | F36: =IFERROR(INDEX(Vendidos!$H:$H,MATCH(E36,Vendidos!$B:$B,0)),"—") | G36: =SUMIF('Fichas Flat'!$E$2:$E$880,E36,'Fichas Flat'!$K$2:$K$880) | H36: =IFERROR(G36/F36,0) | I36: =IFERROR(F36-G36,0) | J36: =IFERROR(I36/F36,0) | K36: =IFERROR(G36/0.3,0) | Q36: 46148 | R36: =IFERROR(IF(M17="","—",H17-N17),"—") | S36: Não | T36: =IFERROR(IF(H17=0,"—",IF(H17<=0.25,"✔ OK",IF(H17<=0.35,"⚠ Atenção","✖ Crítico"))),"—")
A37: Drinks | B37: Sucos | C37: Jarra Suco de Abacaxi com Hortelã | D37: =VLOOKUP(E37,_Protheus_Cadastro!A:I,2,FALSE) | E37: 002032 | F37: =IFERROR(INDEX(Vendidos!$H:$H,MATCH(E37,Vendidos!$B:$B,0)),"—") | G37: =SUMIF('Fichas Flat'!$E$2:$E$880,E37,'Fichas Flat'!$K$2:$K$880) | H37: =IFERROR(G37/F37,0) | I37: =IFERROR(F37-G37,0) | J37: =IFERROR(I37/F37,0) | K37: =IFERROR(G37/0.3,0) | Q37: 46148 | R37: =IFERROR(IF(M18="","—",H18-N18),"—") | S37: Não | T37: =IFERROR(IF(H18=0,"—",IF(H18<=0.25,"✔ OK",IF(H18<=0.35,"⚠ Atenção","✖ Crítico"))),"—")
A38: Drinks | B38: Sucos | C38: Jarra Suco de Abacaxi | D38: =VLOOKUP(E38,_Protheus_Cadastro!A:I,2,FALSE) | E38: 002056 | F38: =IFERROR(INDEX(Vendidos!$H:$H,MATCH(E38,Vendidos!$B:$B,0)),"—") | G38: =SUMIF('Fichas Flat'!$E$2:$E$880,E38,'Fichas Flat'!$K$2:$K$880) | H38: =IFERROR(G38/F38,0) | I38: =IFERROR(F38-G38,0) | J38: =IFERROR(I38/F38,0) | K38: =IFERROR(G38/0.3,0) | Q38: 46148 | R38: =IFERROR(IF(M19="","—",H19-N19),"—") | S38: Não | T38: =IFERROR(IF(H19=0,"—",IF(H19<=0.25,"✔ OK",IF(H19<=0.35,"⚠ Atenção","✖ Crítico"))),"—")
A39: Caipirinhas | B39: Caipirinha | C39: Cachaça do Quintal - Ouro | D39: =VLOOKUP(E39,_Protheus_Cadastro!A:I,2,FALSE) | E39: 000959 | F39: =IFERROR(INDEX(Vendidos!$H:$H,MATCH(E39,Vendidos!$B:$B,0)),"—") | G39: =SUMIF('Fichas Flat'!$E$2:$E$880,E39,'Fichas Flat'!$K$2:$K$880) | H39: =IFERROR(G39/F39,0) | I39: =IFERROR(F39-G39,0) | J39: =IFERROR(I39/F39,0) | K39: =IFERROR(G39/0.3,0) | Q39: 46148 | R39: =IFERROR(IF(M36="","—",H36-N36),"—") | S39: Sim | T39: =IFERROR(IF(H36=0,"—",IF(H36<=0.25,"✔ OK",IF(H36<=0.35,"⚠ Atenção","✖ Crítico"))),"—")
A40: Caipirinhas | B40: Caipirinha | C40: Cachaça do Quintal - Prata | D40: =VLOOKUP(E40,_Protheus_Cadastro!A:I,2,FALSE) | E40: 000958 | F40: =IFERROR(INDEX(Vendidos!$H:$H,MATCH(E40,Vendidos!$B:$B,0)),"—") | G40: =SUMIF('Fichas Flat'!$E$2:$E$880,E40,'Fichas Flat'!$K$2:$K$880) | H40: =IFERROR(G40/F40,0) | I40: =IFERROR(F40-G40,0) | J40: =IFERROR(I40/F40,0) | K40: =IFERROR(G40/0.3,0) | Q40: 46148 | R40: =IFERROR(IF(M37="","—",H37-N37),"—") | S40: Sim | T40: =IFERROR(IF(H37=0,"—",IF(H37<=0.25,"✔ OK",IF(H37<=0.35,"⚠ Atenção","✖ Crítico"))),"—")
...

Sheet Vendidos
A1: Identificação Protheus | H1: Dados ZIG | N1: Locais
A2: Origem | B2: Código Protheus | C2: Nome PA (Protheus) | D2: Tipo | E2: Und. | F2: Estrutura Protheus | G2: Bloqueado Protheus | H2: Preço Venda (ZIG) | I2: SKU ZIG | J2: Nome (ZIG) | K2: Categoria (ZIG) | L2: Status Validação | M2: Situação ZIG | N2: Locais (completo) | O2: Carinás | P2: Lapa | Q2: Tatuapé | R2: Pavão | S2: Chac. | T2: V. Madalena | U2: V. Mariana | V2: Perdizes | W2: Santana | X2: Sto. André | Y2: Del. Carinás | Z2: Del. Lapa | AA2: Del. Tatuapé | AB2: Del. Pavão | AC2: Del. Chac. | AD2: Del. V. Madalena | AE2: Del. V. Mariana | AF2: Del. Perdizes | AG2: Del. Santana | AH2: Del. Sto. André | AI2: Interlagos | AJ2: Quiosque | AK2: Observação
A3: Protheus | B3: 001408 | C3: =IF(B3="—","—",IFERROR(VLOOKUP(B3,_Protheus_Cadastro!$A:$B,2,FALSE),"—")) | D3: =IF(B3="—",IFERROR(INDEX(_ZIG_Cadastro!$D:$D,MATCH(H3,_ZIG_Cadastro!$A:$A,0)),"Produto"),IFERROR(VLOOKUP(B3,_Protheus_Cadastro!$A:$C,3,FALSE),"—")) | E3: =IF(B3="—","—",IFERROR(VLOOKUP(B3,_Protheus_Cadastro!$A:$D,4,FALSE),"—")) | F3: =IF(ISERROR(VLOOKUP(B3,'Estrutura Protheus'!A:A,1,FALSE)),"Não","Sim") | G3: =IFERROR(INDEX(_Protheus_Cadastro!$H:$H,MATCH(B3,_Protheus_Cadastro!$A:$A,0)),"—") | H3: =IFERROR(INDEX(_ZIG_Precos!$D:$D,MATCH(I3,_ZIG_Precos!$F:$F,0)),"—") | I3: =IFERROR(VLOOKUP(B3,_Protheus_Cadastro!$A:$I,9,FALSE),"—") | J3: =IFERROR(INDEX(_ZIG_Cadastro!$B:$B,MATCH(I3,_ZIG_Cadastro!$A:$A,0)),IFERROR(INDEX(_Entradas_ZIG!$B:$B,MATCH(I3,_Entradas_ZIG!$C:$C,0)),"—")) | K3: =IFERROR(INDEX(_ZIG_Cadastro!$C:$C,MATCH(I3,_ZIG_Cadastro!$A:$A,0)),IFERROR(INDEX(_Entradas_ZIG!$D:$D,MATCH(I3,_Entradas_ZIG!$C:$C,0)),"—")) | L3: =IF(I3="","Sem SKU ZIG",IF(I3="—","Sem SKU ZIG",IF(NOT(ISERROR(MATCH(I3,_ZIG_Cadastro!$A:$A,0))),IF(EXACT(UPPER(TRIM(C3)),UPPER(TRIM(INDEX(_ZIG_Cadastro!$B:$B,MATCH(I3,_ZIG_Cadastro!$A:$A,0))))),"OK","Atencao - Nome diverge"),IF(NOT(ISERROR(MATCH(I3,_Entradas_ZIG!$C:$C,0))),"OK","Erro - SKU nao encontrado")))) | M3: =IFERROR(INDEX(_ZIG_Cadastro!$G:$G,MATCH(I3,_ZIG_Cadastro!$A:$A,0)),IF(NOT(ISERROR(MATCH(I3,_Entradas_ZIG!$C:$C,0))),"Ativo","—")) | N3: =IFERROR(INDEX(_ZIG_Cadastro!$E:$E,MATCH(I3,_ZIG_Cadastro!$A:$A,0)),IFERROR(INDEX(_Entradas_ZIG!$F:$F,MATCH(I3,_Entradas_ZIG!$C:$C,0)),"—")) | O3: =IF(AND(ISNUMBER(SEARCH("Espeto",N3)),ISNUMBER(SEARCH("Carin",N3))),"SIM","") | P3: =IF(AND(ISNUMBER(SEARCH("Espeto",N3)),ISNUMBER(SEARCH("Lapa",N3))),"SIM","") | Q3: =IF(AND(ISNUMBER(SEARCH("Espeto",N3)),ISNUMBER(SEARCH("Tatuapé",N3))),"SIM","") | R3: =IF(AND(ISNUMBER(SEARCH("Espeto",N3)),ISNUMBER(SEARCH("Pavão",N3))),"SIM","") | S3: =IF(AND(ISNUMBER(SEARCH("Espeto",N3)),ISNUMBER(SEARCH("Chac",N3))),"SIM","") | T3: =IF(AND(ISNUMBER(SEARCH("Espeto",N3)),ISNUMBER(SEARCH("Madalena",N3))),"SIM","") | U3: =IF(AND(ISNUMBER(SEARCH("Espeto",N3)),ISNUMBER(SEARCH("Mariana",N3))),"SIM","") | V3: =IF(AND(ISNUMBER(SEARCH("Espeto",N3)),ISNUMBER(SEARCH("Perdizes",N3))),"SIM","") | W3: =IF(AND(ISNUMBER(SEARCH("Espeto",N3)),ISNUMBER(SEARCH("Santana",N3))),"SIM","") | X3: =IF(AND(ISNUMBER(SEARCH("Espeto",N3)),ISNUMBER(SEARCH("André",N3))),"SIM","") | Y3: =IF(AND(ISNUMBER(SEARCH("Delivery",N3)),ISNUMBER(SEARCH("Carin",N3))),"SIM","") | Z3: =IF(AND(ISNUMBER(SEARCH("Delivery",N3)),ISNUMBER(SEARCH("Lapa",N3))),"SIM","") | AA3: =IF(AND(ISNUMBER(SEARCH("Delivery",N3)),ISNUMBER(SEARCH("Tatuapé",N3))),"SIM","") | AB3: =IF(AND(ISNUMBER(SEARCH("Delivery",N3)),ISNUMBER(SEARCH("Pavão",N3))),"SIM","") | AC3: =IF(AND(ISNUMBER(SEARCH("Delivery",N3)),ISNUMBER(SEARCH("Chac",N3))),"SIM","") | AD3: =IF(AND(ISNUMBER(SEARCH("Delivery",N3)),ISNUMBER(SEARCH("Madalena",N3))),"SIM","") | AE3: =IF(AND(ISNUMBER(SEARCH("Delivery",N3)),ISNUMBER(SEARCH("Mariana",N3))),"SIM","") | AF3: =IF(AND(ISNUMBER(SEARCH("Delivery",N3)),ISNUMBER(SEARCH("Perdizes",N3))),"SIM","") | AG3: =IF(AND(ISNUMBER(SEARCH("Delivery",N3)),ISNUMBER(SEARCH("Santana",N3))),"SIM","") | AH3: =IF(AND(ISNUMBER(SEARCH("Delivery",N3)),ISNUMBER(SEARCH("André",N3))),"SIM","") | AI3: =IF(ISNUMBER(SEARCH("Interlagos",N3)),"SIM","") | AJ3: =IF(ISNUMBER(SEARCH("Quiosque",N3)),"SIM","")
A4: Protheus | B4: 001257 | C4: =IF(B4="—","—",IFERROR(VLOOKUP(B4,_Protheus_Cadastro!$A:$B,2,FALSE),"—")) | D4: =IF(B4="—",IFERROR(INDEX(_ZIG_Cadastro!$D:$D,MATCH(H4,_ZIG_Cadastro!$A:$A,0)),"Produto"),IFERROR(VLOOKUP(B4,_Protheus_Cadastro!$A:$C,3,FALSE),"—")) | E4: =IF(B4="—","—",IFERROR(VLOOKUP(B4,_Protheus_Cadastro!$A:$D,4,FALSE),"—")) | F4: =IF(ISERROR(VLOOKUP(B4,'Estrutura Protheus'!A:A,1,FALSE)),"Não","Sim") | G4: =IFERROR(INDEX(_Protheus_Cadastro!$H:$H,MATCH(B4,_Protheus_Cadastro!$A:$A,0)),"—") | H4: =IFERROR(INDEX(_ZIG_Precos!$D:$D,MATCH(I4,_ZIG_Precos!$F:$F,0)),"—") | I4: =IFERROR(VLOOKUP(B4,_Protheus_Cadastro!$A:$I,9,FALSE),"—") | J4: =IFERROR(INDEX(_ZIG_Cadastro!$B:$B,MATCH(I4,_ZIG_Cadastro!$A:$A,0)),IFERROR(INDEX(_Entradas_ZIG!$B:$B,MATCH(I4,_Entradas_ZIG!$C:$C,0)),"—")) | K4: =IFERROR(INDEX(_ZIG_Cadastro!$C:$C,MATCH(I4,_ZIG_Cadastro!$A:$A,0)),IFERROR(INDEX(_Entradas_ZIG!$D:$D,MATCH(I4,_Entradas_ZIG!$C:$C,0)),"—")) | L4: =IF(I4="","Sem SKU ZIG",IF(I4="—","Sem SKU ZIG",IF(NOT(ISERROR(MATCH(I4,_ZIG_Cadastro!$A:$A,0))),IF(EXACT(UPPER(TRIM(C4)),UPPER(TRIM(INDEX(_ZIG_Cadastro!$B:$B,MATCH(I4,_ZIG_Cadastro!$A:$A,0))))),"OK","Atencao - Nome diverge"),IF(NOT(ISERROR(MATCH(I4,_Entradas_ZIG!$C:$C,0))),"OK","Erro - SKU nao encontrado")))) | M4: =IFERROR(INDEX(_ZIG_Cadastro!$G:$G,MATCH(I4,_ZIG_Cadastro!$A:$A,0)),IF(NOT(ISERROR(MATCH(I4,_Entradas_ZIG!$C:$C,0))),"Ativo","—")) | N4: =IFERROR(INDEX(_ZIG_Cadastro!$E:$E,MATCH(I4,_ZIG_Cadastro!$A:$A,0)),IFERROR(INDEX(_Entradas_ZIG!$F:$F,MATCH(I4,_Entradas_ZIG!$C:$C,0)),"—")) | O4: =IF(AND(ISNUMBER(SEARCH("Espeto",N4)),ISNUMBER(SEARCH("Carin",N4))),"SIM","") | P4: =IF(AND(ISNUMBER(SEARCH("Espeto",N4)),ISNUMBER(SEARCH("Lapa",N4))),"SIM","") | Q4: =IF(AND(ISNUMBER(SEARCH("Espeto",N4)),ISNUMBER(SEARCH("Tatuapé",N4))),"SIM","") | R4: =IF(AND(ISNUMBER(SEARCH("Espeto",N4)),ISNUMBER(SEARCH("Pavão",N4))),"SIM","") | S4: =IF(AND(ISNUMBER(SEARCH("Espeto",N4)),ISNUMBER(SEARCH("Chac",N4))),"SIM","") | T4: =IF(AND(ISNUMBER(SEARCH("Espeto",N4)),ISNUMBER(SEARCH("Madalena",N4))),"SIM","") | U4: =IF(AND(ISNUMBER(SEARCH("Espeto",N4)),ISNUMBER(SEARCH("Mariana",N4))),"SIM","") | V4: =IF(AND(ISNUMBER(SEARCH("Espeto",N4)),ISNUMBER(SEARCH("Perdizes",N4))),"SIM","") | W4: =IF(AND(ISNUMBER(SEARCH("Espeto",N4)),ISNUMBER(SEARCH("Santana",N4))),"SIM","") | X4: =IF(AND(ISNUMBER(SEARCH("Espeto",N4)),ISNUMBER(SEARCH("André",N4))),"SIM","") | Y4: =IF(AND(ISNUMBER(SEARCH("Delivery",N4)),ISNUMBER(SEARCH("Carin",N4))),"SIM","") | Z4: =IF(AND(ISNUMBER(SEARCH("Delivery",N4)),ISNUMBER(SEARCH("Lapa",N4))),"SIM","") | AA4: =IF(AND(ISNUMBER(SEARCH("Delivery",N4)),ISNUMBER(SEARCH("Tatuapé",N4))),"SIM","") | AB4: =IF(AND(ISNUMBER(SEARCH("Delivery",N4)),ISNUMBER(SEARCH("Pavão",N4))),"SIM","") | AC4: =IF(AND(ISNUMBER(SEARCH("Delivery",N4)),ISNUMBER(SEARCH("Chac",N4))),"SIM","") | AD4: =IF(AND(ISNUMBER(SEARCH("Delivery",N4)),ISNUMBER(SEARCH("Madalena",N4))),"SIM","") | AE4: =IF(AND(ISNUMBER(SEARCH("Delivery",N4)),ISNUMBER(SEARCH("Mariana",N4))),"SIM","") | AF4: =IF(AND(ISNUMBER(SEARCH("Delivery",N4)),ISNUMBER(SEARCH("Perdizes",N4))),"SIM","") | AG4: =IF(AND(ISNUMBER(SEARCH("Delivery",N4)),ISNUMBER(SEARCH("Santana",N4))),"SIM","") | AH4: =IF(AND(ISNUMBER(SEARCH("Delivery",N4)),ISNUMBER(SEARCH("André",N4))),"SIM","") | AI4: =IF(ISNUMBER(SEARCH("Interlagos",N4)),"SIM","") | AJ4: =IF(ISNUMBER(SEARCH("Quiosque",N4)),"SIM","")
